{
  "timestamp": "2025-06-02T13:40:28.614137",
  "total_failures": 5,
  "analyses": [
    {
      "failure_info": {
        "test_name": "v2/tests/unit/test_cards.py::test_card_creation",
        "test_file": "v2/tests/unit/test_cards.py",
        "test_layer": "unit",
        "failure_category": "assertion_error",
        "error_message": "AssertionError: Expected Ace of Spades but got King of Hearts",
        "traceback_info": "File 'v2/core/cards.py', line 25, in __init__\n    assert rank in valid_ranks\nAssertionError",
        "line_number": 25,
        "component_type": "core",
        "timestamp": "2025-06-02T13:40:28.604164",
        "duration": 0.1
      },
      "root_cause_layer": "core",
      "confidence_score": 1.0,
      "analysis_reasoning": "测试 'v2/tests/unit/test_cards.py::test_card_creation' 在 unit 层级失败。失败类型为 assertion_error，主要涉及 core 组件。根据错误模式和组件分析，根本原因可能在 core 层级。错误信息: AssertionError: Expected Ace of Spades but got King of Hearts。",
      "fix_suggestions": [
        "检查核心逻辑的数据结构和算法实现",
        "验证游戏状态的完整性和一致性",
        "检查测试断言的预期值和实际值是否正确",
        "验证测试数据的准备和清理逻辑"
      ],
      "responsibility_assignment": "核心逻辑开发团队",
      "related_components": [
        "core"
      ],
      "severity_level": "HIGH"
    },
    {
      "failure_info": {
        "test_name": "v2/tests/unit/test_controller.py::test_invalid_action",
        "test_file": "v2/tests/unit/test_controller.py",
        "test_layer": "unit",
        "failure_category": "type_error",
        "error_message": "TypeError: PokerController.process_action() takes 2 positional arguments but 3 were given",
        "traceback_info": "File 'v2/controller/poker_controller.py', line 45, in process_action",
        "line_number": 45,
        "component_type": "controller",
        "timestamp": "2025-06-02T13:40:28.605161",
        "duration": 0.05
      },
      "root_cause_layer": "controller",
      "confidence_score": 1.0,
      "analysis_reasoning": "测试 'v2/tests/unit/test_controller.py::test_invalid_action' 在 unit 层级失败。失败类型为 type_error，主要涉及 controller 组件。根据错误模式和组件分析，根本原因可能在 controller 层级。错误信息: TypeError: PokerController.process_action() takes 2 positional arguments but 3 were given。",
      "fix_suggestions": [
        "检查控制器的API接口和参数传递",
        "验证原子操作的事务完整性",
        "检查函数参数的类型和数量",
        "验证数据类型转换的正确性"
      ],
      "responsibility_assignment": "控制器层开发团队",
      "related_components": [
        "controller"
      ],
      "severity_level": "HIGH"
    },
    {
      "failure_info": {
        "test_name": "v2/tests/integration/test_ui_flow.py::test_streamlit_integration",
        "test_file": "v2/tests/integration/test_ui_flow.py",
        "test_layer": "integration",
        "failure_category": "attribute_error",
        "error_message": "AttributeError: 'NoneType' object has no attribute 'session_state'",
        "traceback_info": "File 'v2/ui/streamlit/app.py', line 120, in render_game_state\n    st.session_state.game_data",
        "line_number": 120,
        "component_type": "ui_streamlit",
        "timestamp": "2025-06-02T13:40:28.605161",
        "duration": 0.3
      },
      "root_cause_layer": "ui_streamlit",
      "confidence_score": 0.8500000000000001,
      "analysis_reasoning": "测试 'v2/tests/integration/test_ui_flow.py::test_streamlit_integration' 在 integration 层级失败。失败类型为 attribute_error，主要涉及 ui_streamlit 组件。根据错误模式和组件分析，根本原因可能在 ui_streamlit 层级。错误信息: AttributeError: 'NoneType' object has no attribute 'session_state'。",
      "fix_suggestions": [
        "检查Streamlit组件的状态管理",
        "验证会话状态的持久化和同步",
        "检查对象属性的定义和初始化",
        "验证API接口的一致性",
        "检查组件间的集成和接口匹配"
      ],
      "responsibility_assignment": "Web界面开发团队",
      "related_components": [
        "ui_streamlit",
        "controller"
      ],
      "severity_level": "MEDIUM"
    },
    {
      "failure_info": {
        "test_name": "v2/tests/unit/test_ai.py::test_ai_decision",
        "test_file": "v2/tests/unit/test_ai.py",
        "test_layer": "unit",
        "failure_category": "import_error",
        "error_message": "ImportError: No module named 'v2.ai.advanced_strategy'",
        "traceback_info": "File 'v2/tests/unit/test_ai.py', line 10, in <module>",
        "line_number": 10,
        "component_type": "unknown",
        "timestamp": "2025-06-02T13:40:28.605161",
        "duration": 0.01
      },
      "root_cause_layer": "test_framework",
      "confidence_score": 0.6,
      "analysis_reasoning": "测试 'v2/tests/unit/test_ai.py::test_ai_decision' 在 unit 层级失败。失败类型为 import_error，主要涉及 unknown 组件。根据错误模式和组件分析，根本原因可能在 test_framework 层级。错误信息: ImportError: No module named 'v2.ai.advanced_strategy'。",
      "fix_suggestions": [
        "检查测试用例的设计和实现",
        "验证测试数据和Mock对象的正确性",
        "检查模块导入路径和依赖关系",
        "确认Python路径和虚拟环境配置"
      ],
      "responsibility_assignment": "测试框架维护团队",
      "related_components": [
        "unknown"
      ],
      "severity_level": "LOW"
    },
    {
      "failure_info": {
        "test_name": "v2/tests/e2e/test_full_game.py::test_complete_game_flow",
        "test_file": "v2/tests/e2e/test_full_game.py",
        "test_layer": "e2e",
        "failure_category": "timeout_error",
        "error_message": "TimeoutError: Game flow timed out after 30 seconds",
        "traceback_info": "File 'v2/tests/e2e/test_full_game.py', line 50, in test_complete_game_flow",
        "line_number": 50,
        "component_type": "unknown",
        "timestamp": "2025-06-02T13:40:28.605161",
        "duration": 30.1
      },
      "root_cause_layer": "unknown",
      "confidence_score": 0.8,
      "analysis_reasoning": "测试 'v2/tests/e2e/test_full_game.py::test_complete_game_flow' 在 e2e 层级失败。失败类型为 timeout_error，主要涉及 unknown 组件。根据错误模式和组件分析，根本原因可能在 unknown 层级。错误信息: TimeoutError: Game flow timed out after 30 seconds。",
      "fix_suggestions": [
        "验证端到端流程的完整性"
      ],
      "responsibility_assignment": "需要进一步调查确定责任方",
      "related_components": [
        "ui_streamlit",
        "core",
        "ui_cli",
        "controller",
        "unknown"
      ],
      "severity_level": "MEDIUM"
    }
  ]
}